//qua ci vuole il corpo della funzione: utile mettere tutto in try catch per gestire le eccezioni

#include <exception>
#include <iostream>
#include <random>
#include "biliardo.hpp"

int main(){
   try{

   }catch (std::exception const& e){
    std::cerr << "Caught exception : '"<< e.what() << "'\n";
    return EXIT_FAILURE;
   }catch(...){
    std::cerr << "Caught unknown exception\n";
    return EXIT_FAILURE;
   }



}